<?xml version="1.0" ?>
<robot name="rgbd_robot">
  <!--skid_steer_drive_controller-->
  <gazebo>
    <plugin filename="libgazebo_ros_diff_drive.so" name="skid_steer_drive_controller_la">
      <ros>
        <namespace>/gazebo_model</namespace>
        <argument>/cmd_vel:=mr_cme_vel</argument>
        <argument>/odom:=odom</argument>
      </ros>
      <update_rate>100.0</update_rate>
      <num_wheel_pairs>2</num_wheel_pairs>
      <odometry_frame>odom</odometry_frame>
      <left_joint>front_left_wheel_joint</left_joint>
      <left_joint>back_left_wheel_joint</left_joint>
      <wheel_separation>0.3</wheel_separation>
      <wheel_diameter>0.2</wheel_diameter>
      <right_joint>front_right_wheel_joint</right_joint>
      <right_joint>back_right_wheel_joint</right_joint>
      <wheel_separation>0.3</wheel_separation>
      <wheel_diameter>0.2</wheel_diameter>
      <robot_base_frame>robot_footprint</robot_base_frame>
      <max_wheel_torque>20</max_wheel_torque>
      <publish_odom>true</publish_odom>
      <publish_odom_tf>true</publish_odom_tf>
      <publish_wheel_tf>true</publish_wheel_tf>
      <odom_source>WORLD</odom_source>
    </plugin>
  </gazebo>  
<!-- Stereo camera plugin -->
<gazebo reference="stereo_camera_link">
  <!-- Sensor RGB -->
  <sensor name="camera_sensor" type="camera">
    <always_on>true</always_on>
    <update_rate>30.0</update_rate>
    <visualize>true</visualize>
    <camera>
      <horizontal_fov>1.047</horizontal_fov>
      <image>
        <width>540</width>
        <height>540</height>
        <format>R8G8B8</format>
      </image>
      <clip>
        <near>0.1</near>
        <far>500</far>
      </clip>
    </camera>
    <plugin name="camera_controller" filename="libgazebo_ros_camera.so">
      <ros>
        <namespace>/camera/rgb</namespace>
        <topic_name>image_raw</topic_name>
      </ros>
    </plugin>
  </sensor>

  <!-- Sensor de profundidade -->
  <sensor name="depth_camera_sensor" type="depth">
    <always_on>true</always_on>
    <update_rate>30.0</update_rate>
    <visualize>true</visualize>
    <camera>
      <horizontal_fov>1.047</horizontal_fov>
      <image>
        <width>540</width>
        <height>540</height>
        <format>R8G8B8</format>
      </image>
      <clip>
        <near>0.1</near>
        <far>500</far>
      </clip>
    </camera>
    <plugin name="zed2i" filename="libgazebo_ros_camera.so">
      <ros>
        <namespace>/zed2i/zed_node</namespace>
        <remapping>rgbd/image_raw:=rgb/image_rect_color</remapping>
        <remapping>rgbd/depth/image_raw:=depth/depth_registered</remapping>
        <remapping>camera/rgb/camera_sensor/image_raw:=rgb/image_raw</remapping>
      </ros>
      <camera_name>rgbd</camera_name>
      <frame_name>rgbd_link_optical</frame_name>
      <hack_baseline>0.07</hack_baseline>
      <min_depth>0.05</min_depth>
      <max_depth>10.0</max_depth>
    </plugin>
    <camera_info>
      <k1>0.0</k1>
      <k2>0.0</k2>
      <p1>0.0</p1>
      <p2>0.0</p2>
      <k3>0.0</k3>
    </camera_info>
  </sensor>
</gazebo>

  <!-- hokuyo -->
  <gazebo reference="hokuyo">
    <sensor name="head_hokuyo_sensor" type="ray">
      <pose>0 0 0 0 0 0</pose>
      <visualize>false</visualize>
      <update_rate>40</update_rate>
      <ray>
        <scan>
          <horizontal>
            <samples>720</samples>
            <resolution>1</resolution>
            <min_angle>-1.570796</min_angle>
            <max_angle>1.570796</max_angle>
          </horizontal>
        </scan>
        <range>
          <min>0.10</min>
          <max>30.0</max>
          <resolution>0.01</resolution>
        </range>
        <noise>
          <type>gaussian</type>
          <!-- Noise parameters based on published spec for Hokuyo laser
                achieving "+-30mm" accuracy at range < 10m.  A mean of 0.0m and
                stddev of 0.01m will put 99.7% of samples within 0.03m of the true
                reading. -->
          <mean>0.0</mean>
          <stddev>0.01</stddev>
        </noise>
      </ray>
      <update_rate>30</update_rate>
      <plugin filename="libgazebo_ros_ray_sensor.so" name="hokuyo_plugin">
        <ros>
          <namespace>/gazebo_model</namespace>
          <argument>~/out:=scan</argument>
        </ros>
        <output_type>sensor_msgs/LaserScan</output_type>
      </plugin>
    </sensor>
  </gazebo>
  <!-- IMU -->
  <gazebo reference="imu_link">
    <gravity>true</gravity>
    <sensor name="imu_sensor" type="imu">
      <always_on>true</always_on>
      <update_rate>1000</update_rate>
      <visualize>true</visualize>
      <topic>__default_topic__</topic>
      <plugin filename="libgazebo_ros_imu_sensor.so" name="imu">
        <topicName>trunk_imu</topicName>
        <bodyName>robot_footprint</bodyName>
        <updateRateHZ>1000.0</updateRateHZ>
        <gaussianNoise>0.1</gaussianNoise>
        <xyzOffset>0 0 0</xyzOffset>
        <rpyOffset>0 0 0</rpyOffset>
        <frameName>imu_link</frameName>
      </plugin>  
    <origin rpy="0 0 0" xyz="0 0 0"/>
    </sensor>
  </gazebo>
  <link name="robot_footprint">
    <pose>0 0 0 0 0 0</pose>
    </link>
  <joint name="robot_footprint_joint" type="fixed">
    <origin rpy="0 0 0" xyz="0 0 0"/>
    <parent link="robot_footprint"/>
    <child link="chassis"/>
  </joint>
  <link name="chassis">
    <pose>0 0 0.1 0 0 0</pose>
    <inertial>
      <mass value="15.0"/>
      <origin rpy=" 0 0 0" xyz="0.0 0 0"/>
      <inertia ixx="0.1" ixy="0" ixz="0" iyy="0.1" iyz="0" izz="0.1"/>
    </inertial>
    <collision name="collision">
      <origin rpy=" 0 0 0" xyz="0 0 0"/>
      <geometry>
        <box size=".4 .2 .1"/>
      </geometry>
    </collision>
    <visual name="chassis_visual">
      <origin rpy=" 0 0 0" xyz="0 0 0"/>
      <geometry>
        <box size=".4 .2 .1"/>
      </geometry>
    </visual>
  </link>
  <link name="front_left_wheel">
    <inertial>
      <mass value="5.0"/>
      <origin rpy=" 0 1.5707 1.5707" xyz="0.0 0 0"/>
      <inertia ixx="0.1" ixy="0" ixz="0" iyy="0.1" iyz="0" izz="0.1"/>
    </inertial>
    <visual>
      <origin rpy=" 0 1.5707 1.5707" xyz="0.0 0 0"/>
      <geometry>
        <cylinder length="0.05" radius="0.1"/>
      </geometry>
    </visual>
    <collision>
      <origin rpy=" 0 1.5707 1.5707" xyz="0.0 0 0"/>
      <geometry>
        <cylinder length="0.05" radius="0.1"/>
      </geometry>
    </collision>
  </link>
  <link name="back_left_wheel">
    <inertial>
      <mass value="5.0"/>
      <origin rpy=" 0 1.5707 1.5707" xyz="0.0 0 0"/>
      <inertia ixx="0.1" ixy="0" ixz="0" iyy="0.1" iyz="0" izz="0.1"/>
    </inertial>
    <visual>
      <origin rpy=" 0 1.5707 1.5707" xyz="0.0 0 0"/>
      <geometry>
        <cylinder length="0.05" radius="0.1"/>
      </geometry>
    </visual>
    <collision>
      <origin rpy=" 0 1.5707 1.5707" xyz="0.0 0 0"/>
      <geometry>
        <cylinder length="0.05" radius="0.1"/>
      </geometry>
    </collision>
  </link>
  <link name="front_right_wheel">
    <inertial>
      <mass value="5.0"/>
      <origin rpy=" 0 1.5707 1.5707" xyz="0.0 0 0"/>
      <inertia ixx="0.1" ixy="0" ixz="0" iyy="0.1" iyz="0" izz="0.1"/>
    </inertial>
    <visual>
      <origin rpy=" 0 1.5707 1.5707" xyz="0.0 0 0"/>
      <geometry>
        <cylinder length="0.05" radius="0.1"/>
      </geometry>
    </visual>
    <collision>
      <origin rpy=" 0 1.5707 1.5707" xyz="0.0 0 0"/>
      <geometry>
        <cylinder length="0.05" radius="0.1"/>
      </geometry>
    </collision>
  </link>
  <link name="back_right_wheel">
    <inertial>
      <mass value="5.0"/>
      <origin rpy=" 0 1.5707 1.5707" xyz="0.0 0 0"/>
      <inertia ixx="0.1" ixy="0" ixz="0" iyy="0.1" iyz="0" izz="0.1"/>
    </inertial>
    <visual>
      <origin rpy=" 0 1.5707 1.5707" xyz="0.0 0 0"/>
      <geometry>
        <cylinder length="0.05" radius="0.1"/>
      </geometry>
    </visual>
    <collision>
      <origin rpy=" 0 1.5707 1.5707" xyz="0.0 0 0"/>
      <geometry>
        <cylinder length="0.05" radius="0.1"/>
      </geometry>
    </collision>
  </link>
  <link name="hokuyo">
    <inertial>
      <mass value="1e-5"/>
      <origin rpy=" 0 0 0" xyz="0 0 0"/>
      <inertia ixx="1e-6" ixy="0" ixz="0" iyy="1e-6" iyz="0" izz="1e-6"/>
    </inertial>
    <visual name="hokuyo_visual">
      <origin rpy="0 0 0" xyz="0 0 0"/>
      <geometry>
        <box size="0.05 0.05 0.05"/>
      </geometry>
    </visual>
    <collision name="hokuyo_colision">
      <origin rpy="0 0 0" xyz="0 0 0"/>
      <geometry>
        <box size="0.1 0.1 0.1"/>
      </geometry>
    </collision>
  </link>
  <link name="imu_link">
    <inertial>
      <mass value="0.001"/>
      <origin rpy="0 0 0" xyz="0 0 0"/>
      <inertia ixx="0.0001" ixy="0" ixz="0" iyy="0.0001" iyz="0" izz="0.0001"/>
    </inertial>
    <visual>
      <origin rpy="0 0 0" xyz="0 0 0"/>
      <geometry>
        <box size="0.01 0.01 0.01"/>
      </geometry>
    </visual>
    <collision>
      <origin rpy="0 0 0" xyz="0 0 0"/>
      <geometry>
        <box size=".01 .01 .01"/>
      </geometry>
    </collision>
  </link>
  <!-- Stereo Camera -->
  <link name="stereo_camera_link">
    <inertial>
      <mass value="0.001"/>
      <origin rpy="0 0 0" xyz="0 0 0"/>
      <inertia ixx="0.0001" ixy="0" ixz="0" iyy="0.0001" iyz="0" izz="0.0001"/>
    </inertial>    
    <!-- Visual representation for the stereo camera -->
    <visual>
      <origin xyz="0 0 0" rpy="0 0 1.57"/>
      <geometry>
        <box size="0.1 0.02 0.02"/>
      </geometry>
    </visual>
    <collision>
      <origin rpy="0 0 0" xyz="0 0 0"/>
      <geometry>
        <box size="0.1 .02 .02"/>
      </geometry>
    </collision>    
  </link>
  <!-- Joints connecting components to the root link -->
  <joint name="front_left_wheel_joint" type="continuous">
    <origin rpy="0 0 0" xyz="0.12 0.15 0"/>
    <child link="front_left_wheel"/>
    <parent link="chassis"/>
    <axis rpy="0 0 0" xyz="0 1 0"/>
    <limit effort="10000" velocity="1000"/>
    <dynamics damping="1.0" friction="1.0"/>
  </joint>
  <joint name="front_right_wheel_joint" type="continuous">
    <origin rpy="0 0 0" xyz="0.12 -0.15 0"/>
    <child link="front_right_wheel"/>
    <parent link="chassis"/>
    <axis rpy="0 0 0" xyz="0 1 0"/>
    <limit effort="10000" velocity="1000"/>
    <dynamics damping="1.0" friction="1.0"/>
  </joint>
  <joint name="back_left_wheel_joint" type="continuous">
    <origin rpy="0 0 0" xyz="-0.12 0.15 0"/>
    <child link="back_left_wheel"/>
    <parent link="chassis"/>
    <axis rpy="0 0 0" xyz="0 1 0"/>
    <limit effort="10000" velocity="1000"/>
    <dynamics damping="1.0" friction="1.0"/>
  </joint>
  <joint name="back_right_wheel_joint" type="continuous">
    <origin rpy="0 0 0" xyz="-0.12 -0.15 0"/>
    <child link="back_right_wheel"/>
    <parent link="chassis"/>
    <axis rpy="0 0 0" xyz="0 1 0"/>
    <limit effort="10000" velocity="1000"/>
    <dynamics damping="1.0" friction="1.0"/>
  </joint>
  <joint name="hokuyo_joint" type="fixed">
    <origin rpy="0 0 0" xyz="0.15 0 0.07"/>
    <child link="hokuyo"/>
    <parent link="chassis"/>
    <axis rpy="0 0 0" xyz="0 1 0"/>
  </joint>
  <joint name="imu_joint" type="fixed">
    <origin rpy="0 0 0" xyz="0.15 0 0.12"/>
    <parent link="chassis"/>
    <child link="imu_link"/>
    <axis rpy="0 0 0" xyz="0 1 0"/>
  </joint>
  <joint name="robot_footprint_to_stereo_camera_joint" type="fixed">
    <origin rpy="0 0 0" xyz="0.15 0 0.15"/>
    <parent link="chassis"/>
    <child link="stereo_camera_link"/>
    <axis rpy="0 0 0" xyz="0 0 0"/>
  </joint>  
  <gazebo reference="chassis">
    <material>Gazebo/Blue</material>
  </gazebo>
  <gazebo reference="stereo_camera_link">
    <material>Gazebo/Red</material>
  </gazebo>
  <gazebo reference="hokuyo">
    <material>Gazebo/Black</material>
  </gazebo>
  <gazebo reference="imu">
    <material>Gazebo/Yellow</material>
  </gazebo>
</robot>
